[2024-01-27T02:25:25.206+0000] {taskinstance.py:1956} INFO - Dependencies all met for dep_context=non-requeueable deps ti=<TaskInstance: sales_forecast_pipeline.extract_and_transform manual__2024-01-27T02:25:17.750860+00:00 [queued]>
[2024-01-27T02:25:25.224+0000] {taskinstance.py:1956} INFO - Dependencies all met for dep_context=requeueable deps ti=<TaskInstance: sales_forecast_pipeline.extract_and_transform manual__2024-01-27T02:25:17.750860+00:00 [queued]>
[2024-01-27T02:25:25.224+0000] {taskinstance.py:2170} INFO - Starting attempt 1 of 1
[2024-01-27T02:25:25.247+0000] {taskinstance.py:2191} INFO - Executing <Task(PythonOperator): extract_and_transform> on 2024-01-27 02:25:17.750860+00:00
[2024-01-27T02:25:25.265+0000] {standard_task_runner.py:60} INFO - Started process 6454 to run task
[2024-01-27T02:25:25.271+0000] {standard_task_runner.py:87} INFO - Running: ['***', 'tasks', 'run', 'sales_forecast_pipeline', 'extract_and_transform', 'manual__2024-01-27T02:25:17.750860+00:00', '--job-id', '3', '--raw', '--subdir', 'DAGS_FOLDER/sales_forecast_pipeline.py', '--cfg-path', '/tmp/tmplbedgpo0']
[2024-01-27T02:25:25.274+0000] {standard_task_runner.py:88} INFO - Job 3: Subtask extract_and_transform
[2024-01-27T02:25:25.586+0000] {task_command.py:423} INFO - Running <TaskInstance: sales_forecast_pipeline.extract_and_transform manual__2024-01-27T02:25:17.750860+00:00 [running]> on host 7ae7c919d654
[2024-01-27T02:25:25.694+0000] {taskinstance.py:2480} INFO - Exporting env vars: AIRFLOW_CTX_DAG_OWNER='***' AIRFLOW_CTX_DAG_ID='sales_forecast_pipeline' AIRFLOW_CTX_TASK_ID='extract_and_transform' AIRFLOW_CTX_EXECUTION_DATE='2024-01-27T02:25:17.750860+00:00' AIRFLOW_CTX_TRY_NUMBER='1' AIRFLOW_CTX_DAG_RUN_ID='manual__2024-01-27T02:25:17.750860+00:00'
[2024-01-27T02:25:25.696+0000] {taskinstance.py:2698} ERROR - Task failed with exception
Traceback (most recent call last):
  File "/home/airflow/.local/lib/python3.8/site-packages/airflow/models/taskinstance.py", line 433, in _execute_task
    result = execute_callable(context=context, **execute_callable_kwargs)
  File "/home/airflow/.local/lib/python3.8/site-packages/airflow/operators/python.py", line 199, in execute
    return_value = self.execute_callable()
  File "/home/airflow/.local/lib/python3.8/site-packages/airflow/operators/python.py", line 216, in execute_callable
    return self.python_callable(*self.op_args, **self.op_kwargs)
  File "/opt/airflow/dags/etl.py", line 35, in extract_and_transform
    raw_files = os.listdir(raw_dir)
FileNotFoundError: [Errno 2] No such file or directory: 'data/raw/'
[2024-01-27T02:25:25.706+0000] {taskinstance.py:1138} INFO - Marking task as FAILED. dag_id=sales_forecast_pipeline, task_id=extract_and_transform, execution_date=20240127T022517, start_date=20240127T022525, end_date=20240127T022525
[2024-01-27T02:25:25.729+0000] {standard_task_runner.py:107} ERROR - Failed to execute job 3 for task extract_and_transform ([Errno 2] No such file or directory: 'data/raw/'; 6454)
[2024-01-27T02:25:25.758+0000] {local_task_job_runner.py:234} INFO - Task exited with return code 1
[2024-01-27T02:25:25.785+0000] {taskinstance.py:3280} INFO - 0 downstream tasks scheduled from follow-on schedule check
